[2025-09-06T09:43:32.555+0000] {local_task_job_runner.py:120} INFO - ::group::Pre task execution logs
[2025-09-06T09:43:32.576+0000] {taskinstance.py:2076} INFO - Dependencies all met for dep_context=non-requeueable deps ti=<TaskInstance: dbt_transformations.dbt_run manual__2025-09-06T09:43:27.444371+00:00 [queued]>
[2025-09-06T09:43:32.580+0000] {taskinstance.py:2076} INFO - Dependencies all met for dep_context=requeueable deps ti=<TaskInstance: dbt_transformations.dbt_run manual__2025-09-06T09:43:27.444371+00:00 [queued]>
[2025-09-06T09:43:32.581+0000] {taskinstance.py:2306} INFO - Starting attempt 1 of 1
[2025-09-06T09:43:32.587+0000] {taskinstance.py:2330} INFO - Executing <Task(BashOperator): dbt_run> on 2025-09-06 09:43:27.444371+00:00
[2025-09-06T09:43:32.592+0000] {standard_task_runner.py:90} INFO - Running: ['***', 'tasks', 'run', 'dbt_transformations', 'dbt_run', 'manual__2025-09-06T09:43:27.444371+00:00', '--job-id', '10', '--raw', '--subdir', 'DAGS_FOLDER/dbt_transformations.py', '--cfg-path', '/tmp/tmpozqto1of']
[2025-09-06T09:43:32.593+0000] {logging_mixin.py:188} WARNING - /home/***/.local/lib/python3.12/site-packages/***/task/task_runner/standard_task_runner.py:62 DeprecationWarning: This process (pid=220) is multi-threaded, use of fork() may lead to deadlocks in the child.
[2025-09-06T09:43:32.593+0000] {standard_task_runner.py:91} INFO - Job 10: Subtask dbt_run
[2025-09-06T09:43:32.593+0000] {standard_task_runner.py:64} INFO - Started process 221 to run task
[2025-09-06T09:43:32.620+0000] {task_command.py:426} INFO - Running <TaskInstance: dbt_transformations.dbt_run manual__2025-09-06T09:43:27.444371+00:00 [running]> on host 11092d7efcaf
[2025-09-06T09:43:32.663+0000] {taskinstance.py:2648} INFO - Exporting env vars: AIRFLOW_CTX_DAG_OWNER='***' AIRFLOW_CTX_DAG_ID='dbt_transformations' AIRFLOW_CTX_TASK_ID='dbt_run' AIRFLOW_CTX_EXECUTION_DATE='2025-09-06T09:43:27.444371+00:00' AIRFLOW_CTX_TRY_NUMBER='1' AIRFLOW_CTX_DAG_RUN_ID='manual__2025-09-06T09:43:27.444371+00:00'
[2025-09-06T09:43:32.664+0000] {taskinstance.py:430} INFO - ::endgroup::
[2025-09-06T09:43:32.672+0000] {subprocess.py:63} INFO - Tmp dir root location: /tmp
[2025-09-06T09:43:32.673+0000] {subprocess.py:75} INFO - Running command: ['/usr/bin/bash', '-c', 'export PATH="$PATH:/home/***/.local/bin" && cd /opt/***/dbt && DBT_PROFILES_DIR="/opt/***/dbt/profiles" dbt run --project-dir . --profiles-dir "/opt/***/dbt/profiles"']
[2025-09-06T09:43:32.679+0000] {subprocess.py:86} INFO - Output:
[2025-09-06T09:43:34.138+0000] {subprocess.py:93} INFO - Usage: dbt run [OPTIONS]
[2025-09-06T09:43:34.139+0000] {subprocess.py:93} INFO - Try 'dbt run -h' for help.
[2025-09-06T09:43:34.139+0000] {subprocess.py:93} INFO - 
[2025-09-06T09:43:34.139+0000] {subprocess.py:93} INFO - Error: Invalid value for '--profiles-dir': Path '/opt/***/dbt/profiles' does not exist.
[2025-09-06T09:43:34.283+0000] {subprocess.py:97} INFO - Command exited with return code 2
[2025-09-06T09:43:34.284+0000] {taskinstance.py:441} INFO - ::group::Post task execution logs
[2025-09-06T09:43:34.291+0000] {taskinstance.py:2905} ERROR - Task failed with exception
Traceback (most recent call last):
  File "/home/airflow/.local/lib/python3.12/site-packages/airflow/models/taskinstance.py", line 465, in _execute_task
    result = _execute_callable(context=context, **execute_callable_kwargs)
             ^^^^^^^^^^^^^^^^^^^^^^^^^^^^^^^^^^^^^^^^^^^^^^^^^^^^^^^^^^^^^
  File "/home/airflow/.local/lib/python3.12/site-packages/airflow/models/taskinstance.py", line 432, in _execute_callable
    return execute_callable(context=context, **execute_callable_kwargs)
           ^^^^^^^^^^^^^^^^^^^^^^^^^^^^^^^^^^^^^^^^^^^^^^^^^^^^^^^^^^^^
  File "/home/airflow/.local/lib/python3.12/site-packages/airflow/models/baseoperator.py", line 401, in wrapper
    return func(self, *args, **kwargs)
           ^^^^^^^^^^^^^^^^^^^^^^^^^^^
  File "/home/airflow/.local/lib/python3.12/site-packages/airflow/operators/bash.py", line 243, in execute
    raise AirflowException(
airflow.exceptions.AirflowException: Bash command failed. The command returned a non-zero exit code 2.
[2025-09-06T09:43:34.293+0000] {taskinstance.py:1206} INFO - Marking task as FAILED. dag_id=dbt_transformations, task_id=dbt_run, run_id=manual__2025-09-06T09:43:27.444371+00:00, execution_date=20250906T094327, start_date=20250906T094332, end_date=20250906T094334
[2025-09-06T09:43:34.300+0000] {standard_task_runner.py:110} ERROR - Failed to execute job 10 for task dbt_run (Bash command failed. The command returned a non-zero exit code 2.; 221)
[2025-09-06T09:43:34.316+0000] {local_task_job_runner.py:243} INFO - Task exited with return code 1
[2025-09-06T09:43:34.329+0000] {taskinstance.py:3503} INFO - 0 downstream tasks scheduled from follow-on schedule check
[2025-09-06T09:43:34.332+0000] {local_task_job_runner.py:222} INFO - ::endgroup::
