[2025-09-06T09:21:23.445+0000] {local_task_job_runner.py:120} INFO - ::group::Pre task execution logs
[2025-09-06T09:21:23.466+0000] {taskinstance.py:2076} INFO - Dependencies all met for dep_context=non-requeueable deps ti=<TaskInstance: load_customers_to_postgres.wait_for_csv manual__2025-09-06T09:21:21.359858+00:00 [queued]>
[2025-09-06T09:21:23.470+0000] {taskinstance.py:2076} INFO - Dependencies all met for dep_context=requeueable deps ti=<TaskInstance: load_customers_to_postgres.wait_for_csv manual__2025-09-06T09:21:21.359858+00:00 [queued]>
[2025-09-06T09:21:23.471+0000] {taskinstance.py:2306} INFO - Starting attempt 1 of 2
[2025-09-06T09:21:23.477+0000] {taskinstance.py:2330} INFO - Executing <Task(FileSensor): wait_for_csv> on 2025-09-06 09:21:21.359858+00:00
[2025-09-06T09:21:23.482+0000] {standard_task_runner.py:90} INFO - Running: ['***', 'tasks', 'run', 'load_customers_to_postgres', 'wait_for_csv', 'manual__2025-09-06T09:21:21.359858+00:00', '--job-id', '5', '--raw', '--subdir', 'DAGS_FOLDER/load_customers_to_postgres.py', '--cfg-path', '/tmp/tmpyttm_mdp']
[2025-09-06T09:21:23.483+0000] {standard_task_runner.py:91} INFO - Job 5: Subtask wait_for_csv
[2025-09-06T09:21:23.483+0000] {logging_mixin.py:188} WARNING - /home/***/.local/lib/python3.12/site-packages/***/task/task_runner/standard_task_runner.py:62 DeprecationWarning: This process (pid=209) is multi-threaded, use of fork() may lead to deadlocks in the child.
[2025-09-06T09:21:23.484+0000] {standard_task_runner.py:64} INFO - Started process 210 to run task
[2025-09-06T09:21:23.510+0000] {task_command.py:426} INFO - Running <TaskInstance: load_customers_to_postgres.wait_for_csv manual__2025-09-06T09:21:21.359858+00:00 [running]> on host 2cd4a0d9f61c
[2025-09-06T09:21:23.558+0000] {taskinstance.py:2648} INFO - Exporting env vars: AIRFLOW_CTX_DAG_OWNER='etl' AIRFLOW_CTX_DAG_ID='load_customers_to_postgres' AIRFLOW_CTX_TASK_ID='wait_for_csv' AIRFLOW_CTX_EXECUTION_DATE='2025-09-06T09:21:21.359858+00:00' AIRFLOW_CTX_TRY_NUMBER='1' AIRFLOW_CTX_DAG_RUN_ID='manual__2025-09-06T09:21:21.359858+00:00'
[2025-09-06T09:21:23.559+0000] {taskinstance.py:430} INFO - ::endgroup::
[2025-09-06T09:21:23.559+0000] {baseoperator.py:400} WARNING - FileSensor.execute cannot be called outside TaskInstance!
[2025-09-06T09:21:23.565+0000] {taskinstance.py:441} INFO - ::group::Post task execution logs
[2025-09-06T09:21:23.570+0000] {taskinstance.py:2905} ERROR - Task failed with exception
Traceback (most recent call last):
  File "/home/airflow/.local/lib/python3.12/site-packages/airflow/models/taskinstance.py", line 465, in _execute_task
    result = _execute_callable(context=context, **execute_callable_kwargs)
             ^^^^^^^^^^^^^^^^^^^^^^^^^^^^^^^^^^^^^^^^^^^^^^^^^^^^^^^^^^^^^
  File "/home/airflow/.local/lib/python3.12/site-packages/airflow/models/taskinstance.py", line 432, in _execute_callable
    return execute_callable(context=context, **execute_callable_kwargs)
           ^^^^^^^^^^^^^^^^^^^^^^^^^^^^^^^^^^^^^^^^^^^^^^^^^^^^^^^^^^^^
  File "/home/airflow/.local/lib/python3.12/site-packages/airflow/models/baseoperator.py", line 401, in wrapper
    return func(self, *args, **kwargs)
           ^^^^^^^^^^^^^^^^^^^^^^^^^^^
  File "/home/airflow/.local/lib/python3.12/site-packages/airflow/sensors/filesystem.py", line 99, in execute
    super().execute(context=context)
  File "/home/airflow/.local/lib/python3.12/site-packages/airflow/models/baseoperator.py", line 401, in wrapper
    return func(self, *args, **kwargs)
           ^^^^^^^^^^^^^^^^^^^^^^^^^^^
  File "/home/airflow/.local/lib/python3.12/site-packages/airflow/sensors/base.py", line 264, in execute
    raise e
  File "/home/airflow/.local/lib/python3.12/site-packages/airflow/sensors/base.py", line 246, in execute
    poke_return = self.poke(context)
                  ^^^^^^^^^^^^^^^^^^
  File "/home/airflow/.local/lib/python3.12/site-packages/airflow/sensors/filesystem.py", line 85, in poke
    self.log.info("Poking for file %s", self.path)
                                        ^^^^^^^^^
  File "/usr/local/lib/python3.12/functools.py", line 995, in __get__
    val = self.func(instance)
          ^^^^^^^^^^^^^^^^^^^
  File "/home/airflow/.local/lib/python3.12/site-packages/airflow/sensors/filesystem.py", line 79, in path
    hook = FSHook(self.fs_conn_id)
           ^^^^^^^^^^^^^^^^^^^^^^^
  File "/home/airflow/.local/lib/python3.12/site-packages/airflow/hooks/filesystem.py", line 64, in __init__
    conn = self.get_connection(fs_conn_id)
           ^^^^^^^^^^^^^^^^^^^^^^^^^^^^^^^
  File "/home/airflow/.local/lib/python3.12/site-packages/airflow/hooks/base.py", line 83, in get_connection
    conn = Connection.get_connection_from_secrets(conn_id)
           ^^^^^^^^^^^^^^^^^^^^^^^^^^^^^^^^^^^^^^^^^^^^^^^
  File "/home/airflow/.local/lib/python3.12/site-packages/airflow/models/connection.py", line 519, in get_connection_from_secrets
    raise AirflowNotFoundException(f"The conn_id `{conn_id}` isn't defined")
airflow.exceptions.AirflowNotFoundException: The conn_id `fs_default` isn't defined
[2025-09-06T09:21:23.573+0000] {taskinstance.py:1206} INFO - Marking task as UP_FOR_RETRY. dag_id=load_customers_to_postgres, task_id=wait_for_csv, run_id=manual__2025-09-06T09:21:21.359858+00:00, execution_date=20250906T092121, start_date=20250906T092123, end_date=20250906T092123
[2025-09-06T09:21:23.579+0000] {standard_task_runner.py:110} ERROR - Failed to execute job 5 for task wait_for_csv (The conn_id `fs_default` isn't defined; 210)
[2025-09-06T09:21:23.585+0000] {local_task_job_runner.py:243} INFO - Task exited with return code 1
[2025-09-06T09:21:23.600+0000] {taskinstance.py:3503} INFO - 0 downstream tasks scheduled from follow-on schedule check
[2025-09-06T09:21:23.601+0000] {local_task_job_runner.py:222} INFO - ::endgroup::
